Workbook

Sheet 説明
B2: 線形判別分析ツール | N2: 簡易手順書.html | Q2: こちらも参照
B4: ★ | C4: 準備するファイル（データ） | N4: ★ | O4: ツールの実行
B6: ★ | C6: 学習ファイル：もとになる調査データ | O6: DiscriminantAnalysis.exe | T6: ダブルクリック
C8: 1行目：項目名
C9: A列：SAMPLENUMBER・ID（固定）
C10: B列～：クラスター算出に使用したデータ（特徴量：SA・MA(0/1)・数値データ）
C11: 最終列：クラスター（グループ）
C13: クラスターを算出に使用した特徴量とクラスターを組みにする
B25: ★ | C25: テストファイル：新規の調査データ | N25: ★ | O25: 出力ファイル
C27: 1行目：項目名 | O27: 右端に 判別結果（予測グループ） を付加したテストファイル
C28: A列：SAMPLENUMBER・ID（固定）
C29: B列～：学習ファイルと同じ項目データ（特徴量：SA・MA(0/1)・数値データ）
C30: 最終列：無し（学習ファイルより1列少ない。クラスター列は含めない）
C32: （例外）精度検証時のみ：最終列名を cluster / label / target にすると、正解列として扱われ「テスト判別率」が出力される
N38: ★ | O38: レポートファイル
O40: クラス（coef_1～intercept）は判別関数の係数と定数項
O41: 標準化したデータと各クラスの係数(coef)を掛けて合計し、そのクラスの定数項(intercept)を加えた値が最大になるグループが判別結果になる
O42: Excelで再計算すると誤差（計算誤差・丸め誤差）で若干異なることがある
O43: レポートにはLOOCV精度・テスト判別率・クラス別分散のコメントも追加 （詳細は簡易手順書.html参照）
O45: R（LDA）での線形判別分析結果とは一致
O46: SPSSの既定（/CLASSIFY=POOLED）とはおおむね一致（Rの結果とも一致）。 差が出る主な原因は「オプションの違い」に起因し、特に次の2点が大きい： ①/CLASSIFY=SEPARATEを指定した場合はQDA相当（正準判別関数の空間でクラスごとに別の共分散を使う）になり、本ツール（LDA=POOLED相当）とは前提が異なるため差が大きくなる ②/PRIORS EQUAL（均等事前確率）を指定した場合、本ツールは件数比率を使うため差が出る

Sheet 検証⇒

Sheet アイリス(1)
A2: irisデータで検証
B4: アヤメの測定データ。ランダムに学習用とテスト用に分ける
I6: ⇒
B7: 全データ | C7: =COUNT(B12:B161) | J7: 学習用 | K7: =COUNT(J12:J116) | Q7: テスト用 | R7: =COUNT(Q12:Q88)
B8: iris.csv | J8: iris1.csv | Q8: iris2.csv | V8: ↓分析時は除外
H9: 文字データを | V9: 「正解」として
H10: 数値に置換 | V10: 検証時に使用
B11: no | C11: sepal_length | D11: sepal_width | E11: petal_length | F11: petal_width | G11: species | H11: species | J11: no | K11: sepal_length | L11: sepal_width | M11: petal_length | N11: petal_width | O11: species | Q11: no | R11: sepal_length | S11: sepal_width | T11: petal_length | U11: petal_width | V11: species
B12: 1 | C12: 5.1 | D12: 3.5 | E12: 1.4 | F12: 0.2 | G12: setosa | H12: 1 | J12: 34 | K12: 5.5 | L12: 4.2 | M12: 1.4 | N12: 0.2 | O12: 1 | Q12: 86 | R12: 6 | S12: 3.4 | T12: 4.5 | U12: 1.6 | V12: 2
B13: 2 | C13: 4.9 | D13: 3 | E13: 1.4 | F13: 0.2 | G13: setosa | H13: 1 | J13: 68 | K13: 5.8 | L13: 2.7 | M13: 4.1 | N13: 1 | O13: 2 | Q13: 58 | R13: 4.9 | S13: 2.4 | T13: 3.3 | U13: 1 | V13: 2
B14: 3 | C14: 4.7 | D14: 3.2 | E14: 1.3 | F14: 0.2 | G14: setosa | H14: 1 | J14: 85 | K14: 5.4 | L14: 3 | M14: 4.5 | N14: 1.5 | O14: 2 | Q14: 7 | R14: 4.6 | S14: 3.4 | T14: 1.4 | U14: 0.3 | V14: 1
B15: 4 | C15: 4.6 | D15: 3.1 | E15: 1.5 | F15: 0.2 | G15: setosa | H15: 1 | J15: 144 | K15: 6.8 | L15: 3.2 | M15: 5.9 | N15: 2.3 | O15: 3 | Q15: 32 | R15: 5.4 | S15: 3.4 | T15: 1.5 | U15: 0.4 | V15: 1
B16: 5 | C16: 5 | D16: 3.6 | E16: 1.4 | F16: 0.2 | G16: setosa | H16: 1 | J16: 122 | K16: 5.6 | L16: 2.8 | M16: 4.9 | N16: 2 | O16: 3 | Q16: 21 | R16: 5.4 | S16: 3.4 | T16: 1.7 | U16: 0.2 | V16: 1
B17: 6 | C17: 5.4 | D17: 3.9 | E17: 1.7 | F17: 0.4 | G17: setosa | H17: 1 | J17: 105 | K17: 6.5 | L17: 3 | M17: 5.8 | N17: 2.2 | O17: 3 | Q17: 27 | R17: 5 | S17: 3.4 | T17: 1.6 | U17: 0.4 | V17: 1
B18: 7 | C18: 4.6 | D18: 3.4 | E18: 1.4 | F18: 0.3 | G18: setosa | H18: 1 | J18: 12 | K18: 4.8 | L18: 3.4 | M18: 1.6 | N18: 0.2 | O18: 1 | Q18: 103 | R18: 7.1 | S18: 3 | T18: 5.9 | U18: 2.1 | V18: 3
B19: 8 | C19: 5 | D19: 3.4 | E19: 1.5 | F19: 0.2 | G19: setosa | H19: 1 | J19: 125 | K19: 6.7 | L19: 3.3 | M19: 5.7 | N19: 2.1 | O19: 3 | Q19: 139 | R19: 6 | S19: 3 | T19: 4.8 | U19: 1.8 | V19: 3
B20: 9 | C20: 4.4 | D20: 2.9 | E20: 1.4 | F20: 0.2 | G20: setosa | H20: 1 | J20: 72 | K20: 6.1 | L20: 2.8 | M20: 4 | N20: 1.3 | O20: 2 | Q20: 140 | R20: 6.9 | S20: 3.1 | T20: 5.4 | U20: 2.1 | V20: 3
B21: 10 | C21: 4.9 | D21: 3.1 | E21: 1.5 | F21: 0.1 | G21: setosa | H21: 1 | J21: 31 | K21: 4.8 | L21: 3.1 | M21: 1.6 | N21: 0.2 | O21: 1 | Q21: 150 | R21: 5.9 | S21: 3 | T21: 5.1 | U21: 1.8 | V21: 3
B22: 11 | C22: 5.4 | D22: 3.7 | E22: 1.5 | F22: 0.2 | G22: setosa | H22: 1 | J22: 51 | K22: 7 | L22: 3.2 | M22: 4.7 | N22: 1.4 | O22: 2 | Q22: 93 | R22: 5.8 | S22: 2.6 | T22: 4 | U22: 1.2 | V22: 2
B23: 12 | C23: 4.8 | D23: 3.4 | E23: 1.6 | F23: 0.2 | G23: setosa | H23: 1 | J23: 63 | K23: 6 | L23: 2.2 | M23: 4 | N23: 1 | O23: 2 | Q23: 78 | R23: 6.7 | S23: 3 | T23: 5 | U23: 1.7 | V23: 2
... B56: 45 | C56: 5.1 | D56: 3.8 | E56: 1.9 | F56: 0.4 | G56: setosa | H56: 1 | J56: 108 | K56: 7.3 | L56: 2.9 | M56: 6.3 | N56: 1.8 | O56: 3 | Q56: 132 | R56: 7.9 | S56: 3.8 | T56: 6.4 | U56: 2 | V56: 3
B57: 46 | C57: 4.8 | D57: 3 | E57: 1.4 | F57: 0.3 | G57: setosa | H57: 1 | J57: 81 | K57: 5.5 | L57: 2.4 | M57: 3.8 | N57: 1.1 | O57: 2
B58: 47 | C58: 5.1 | D58: 3.8 | E58: 1.6 | F58: 0.2 | G58: setosa | H58: 1 | J58: 59 | K58: 6.6 | L58: 2.9 | M58: 4.6 | N58: 1.3 | O58: 2
B59: 48 | C59: 4.6 | D59: 3.2 | E59: 1.4 | F59: 0.2 | G59: setosa | H59: 1 | J59: 116 | K59: 6.4 | L59: 3.2 | M59: 5.3 | N59: 2.3 | O59: 3
B60: 49 | C60: 5.3 | D60: 3.7 | E60: 1.5 | F60: 0.2 | G60: setosa | H60: 1 | J60: 10 | K60: 4.9 | L60: 3.1 | M60: 1.5 | N60: 0.1 | O60: 1
B61: 50 | C61: 5 | D61: 3.3 | E61: 1.4 | F61: 0.2 | G61: setosa | H61: 1 | J61: 6 | K61: 5.4 | L61: 3.9 | M61: 1.7 | N61: 0.4 | O61: 1
B62: 51 | C62: 7 | D62: 3.2 | E62: 4.7 | F62: 1.4 | G62: versicolor | H62: 2 | J62: 90 | K62: 5.5 | L62: 2.5 | M62: 4 | N62: 1.3 | O62: 2
B63: 52 | C63: 6.4 | D63: 3.2 | E63: 4.5 | F63: 1.5 | G63: versicolor | H63: 2 | J63: 75 | K63: 6.4 | L63: 2.9 | M63: 4.3 | N63: 1.3 | O63: 2
B64: 53 | C64: 6.9 | D64: 3.1 | E64: 4.9 | F64: 1.5 | G64: versicolor | H64: 2 | J64: 77 | K64: 6.8 | L64: 2.8 | M64: 4.8 | N64: 1.4 | O64: 2
B65: 54 | C65: 5.5 | D65: 2.3 | E65: 4 | F65: 1.3 | G65: versicolor | H65: 2 | J65: 70 | K65: 5.6 | L65: 2.5 | M65: 3.9 | N65: 1.1 | O65: 2
B66: 55 | C66: 6.5 | D66: 2.8 | E66: 4.6 | F66: 1.5 | G66: versicolor | H66: 2 | J66: 60 | K66: 5.2 | L66: 2.7 | M66: 3.9 | N66: 1.4 | O66: 2
B67: 56 | C67: 5.7 | D67: 2.8 | E67: 4.5 | F67: 1.3 | G67: versicolor | H67: 2 | J67: 11 | K67: 5.4 | L67: 3.7 | M67: 1.5 | N67: 0.2 | O67: 1
B68: 57 | C68: 6.3 | D68: 3.3 | E68: 4.7 | F68: 1.6 | G68: versicolor | H68: 2 | J68: 114 | K68: 5.7 | L68: 2.5 | M68: 5 | N68: 2 | O68: 3
... B116: 105 | C116: 6.5 | D116: 3 | E116: 5.8 | F116: 2.2 | G116: virginica | H116: 3 | J116: 107 | K116: 4.9 | L116: 2.5 | M116: 4.5 | N116: 1.7 | O116: 3
B117: 106 | C117: 7.6 | D117: 3 | E117: 6.6 | F117: 2.1 | G117: virginica | H117: 3
B118: 107 | C118: 4.9 | D118: 2.5 | E118: 4.5 | F118: 1.7 | G118: virginica | H118: 3
B119: 108 | C119: 7.3 | D119: 2.9 | E119: 6.3 | F119: 1.8 | G119: virginica | H119: 3
B120: 109 | C120: 6.7 | D120: 2.5 | E120: 5.8 | F120: 1.8 | G120: virginica | H120: 3
B121: 110 | C121: 7.2 | D121: 3.6 | E121: 6.1 | F121: 2.5 | G121: virginica | H121: 3
B122: 111 | C122: 6.5 | D122: 3.2 | E122: 5.1 | F122: 2 | G122: virginica | H122: 3
...

Sheet アイリス(2)
A2: irisデータで検証
B4: レポートファイル | I4: テスト用＋予測グループ
N6: 答え合わせ
N7: 正解率 | O7: =COUNTIF($P$9:$P$81,"TRUE")/COUNT($I$9:$I$81)
B8: item | C8: value | I8: no | J8: sepal_length | K8: sepal_width | L8: petal_length | M8: petal_width | N8: predicted_label | O8: ='アイリス(1)'!V11 | P8: match
B9: 学習判別率 | C9: 0.99047619 | I9: 86 | J9: 6 | K9: 3.4 | L9: 4.5 | M9: 1.6 | N9: 2 | O9: ='アイリス(1)'!V12 | P9: =O9=N9
I10: 58 | J10: 4.9 | K10: 2.4 | L10: 3.3 | M10: 1 | N10: 2 | O10: ='アイリス(1)'!V13 | P10: =O10=N10
B11: 学習データクロス集計 | C11: 予測グループ | I11: 7 | J11: 4.6 | K11: 3.4 | L11: 1.4 | M11: 0.3 | N11: 1 | O11: ='アイリス(1)'!V14 | P11: =O11=N11
B12: クラスター | C12: 1 | D12: 2 | E12: 3 | F12: 合計 | I12: 32 | J12: 5.4 | K12: 3.4 | L12: 1.5 | M12: 0.4 | N12: 1 | O12: ='アイリス(1)'!V15 | P12: =O12=N12
B13: 1 | C13: 35 | D13: 0 | E13: 0 | F13: 35 | I13: 21 | J13: 5.4 | K13: 3.4 | L13: 1.7 | M13: 0.2 | N13: 1 | O13: ='アイリス(1)'!V16 | P13: =O13=N13
B14: 2 | C14: 0 | D14: 34 | E14: 1 | F14: 35 | I14: 27 | J14: 5 | K14: 3.4 | L14: 1.6 | M14: 0.4 | N14: 1 | O14: ='アイリス(1)'!V17 | P14: =O14=N14
B15: 3 | C15: 0 | D15: 0 | E15: 35 | F15: 35 | I15: 103 | J15: 7.1 | K15: 3 | L15: 5.9 | M15: 2.1 | N15: 3 | O15: ='アイリス(1)'!V18 | P15: =O15=N15
B16: 合計 | C16: 35 | D16: 34 | E16: 36 | F16: 105 | I16: 139 | J16: 6 | K16: 3 | L16: 4.8 | M16: 1.8 | N16: 3 | O16: ='アイリス(1)'!V19 | P16: =O16=N16
I17: 140 | J17: 6.9 | K17: 3.1 | L17: 5.4 | M17: 2.1 | N17: 3 | O17: ='アイリス(1)'!V20 | P17: =O17=N17
B18: 標準化 | C18: 平均=0, 分散=1 (自前 StandardScaler 適用済み) | I18: 150 | J18: 5.9 | K18: 3 | L18: 5.1 | M18: 1.8 | N18: 3 | O18: ='アイリス(1)'!V21 | P18: =O18=N18
I19: 93 | J19: 5.8 | K19: 2.6 | L19: 4 | M19: 1.2 | N19: 2 | O19: ='アイリス(1)'!V22 | P19: =O19=N19
B20: クラスラベル | C20: 1 | D20: 2 | E20: 3 | I20: 78 | J20: 6.7 | K20: 3 | L20: 5 | M20: 1.7 | N20: 2 | O20: ='アイリス(1)'!V23 | P20: =O20=N20
B21: クラス事前確率 | C21: 0.33333333 | D21: 0.33333333 | E21: 0.33333333 | I21: 33 | J21: 5.2 | K21: 4.1 | L21: 1.5 | M21: 0.1 | N21: 1 | O21: ='アイリス(1)'!V24 | P21: =O21=N21
I22: 142 | J22: 6.9 | K22: 3.1 | L22: 5.1 | M22: 2.3 | N22: 3 | O22: ='アイリス(1)'!V25 | P22: =O22=N22
B23: クラス | C23: coef_1 | D23: coef_2 | E23: coef_3 | F23: coef_4 | I23: 98 | J23: 6.2 | K23: 2.9 | L23: 4.3 | M23: 1.3 | N23: 2 | O23: ='アイリス(1)'!V26 | P23: =O23=N23
B24: クラス 1 | C24: 6.6063288 | D24: 7.1333743 | E24: -35.8105 | F24: -22.105936 | I24: 113 | J24: 6.8 | K24: 3 | L24: 5.5 | M24: 2.1 | N24: 3 | O24: ='アイリス(1)'!V27 | P24: =O24=N24
B25: クラス 2 | C25: -1.2697106 | D25: -2.4006814 | E25: 8.9532478 | F25: 4.2400763 | I25: 124 | J25: 6.3 | K25: 2.7 | L25: 4.9 | M25: 1.8 | N25: 3 | O25: ='アイリス(1)'!V28 | P25: =O25=N25
B26: クラス 3 | C26: -5.3366182 | D26: -4.7326929 | E26: 26.857252 | F26: 17.86586 | I26: 41 | J26: 5 | K26: 3.5 | L26: 1.3 | M26: 0.3 | N26: 1 | O26: ='アイリス(1)'!V29 | P26: =O26=N26
I27: 29 | J27: 5.2 | K27: 3.4 | L27: 1.4 | M27: 0.2 | N27: 1 | O27: ='アイリス(1)'!V30 | P27: =O27=N27
B28: クラス | C28: intercept | I28: 39 | J28: 4.4 | K28: 3 | L28: 1.3 | M28: 0.2 | N28: 1 | O28: ='アイリス(1)'!V31 | P28: =O28=N28
B29: クラス 1 | C29: -38.491585 | I29: 40 | J29: 5.1 | K29: 3.4 | L29: 1.5 | M29: 0.2 | N29: 1 | O29: ='アイリス(1)'!V32 | P29: =O29=N29
B30: クラス 2 | C30: -3.4651145 | I30: 76 | J30: 6.6 | K30: 3 | L30: 4.4 | M30: 1.4 | N30: 2 | O30: ='アイリス(1)'!V33 | P30: =O30=N30
B31: クラス 3 | C31: -22.82079 | I31: 15 | J31: 5.8 | K31: 4 | L31: 1.2 | M31: 0.2 | N31: 1 | O31: ='アイリス(1)'!V34 | P31: =O31=N31
I32: 101 | J32: 6.3 | K32: 3.3 | L32: 6 | M32: 2.5 | N32: 3 | O32: ='アイリス(1)'!V35 | P32: =O32=N32
B33: 標準化平均 | C33: mean_1 | D33: mean_2 | E33: mean_3 | F33: mean_4 | I33: 80 | J33: 5.7 | K33: 2.6 | L33: 3.5 | M33: 1 | N33: 2 | O33: ='アイリス(1)'!V36 | P33: =O33=N33
B34: 値 | C34: 5.8047619 | D34: 3.0438095 | E34: 3.7504762 | F34: 1.2057143 | I34: 37 | J34: 5.5 | K34: 3.5 | L34: 1.3 | M34: 0.2 | N34: 1 | O34: ='アイリス(1)'!V37 | P34: =O34=N34
I35: 8 | J35: 5 | K35: 3.4 | L35: 1.5 | M35: 0.2 | N35: 1 | O35: ='アイリス(1)'!V38 | P35: =O35=N35
B36: 標準化分散 | C36: var_1 | D36: var_2 | E36: var_3 | F36: var_4 | I36: 84 | J36: 6 | K36: 2.7 | L36: 5.1 | M36: 1.6 | N36: 3 | O36: ='アイリス(1)'!V39 | P36: =O36=N36
B37: 値 | C37: 0.63607256 | D37: 0.19236644 | E37: 2.9775474 | F37: 0.57444354 | I37: 130 | J37: 7.2 | K37: 3 | L37: 5.8 | M37: 1.6 | N37: 3 | O37: ='アイリス(1)'!V40 | P37: =O37=N37
I38: 42 | J38: 4.5 | K38: 2.3 | L38: 1.3 | M38: 0.3 | N38: 1 | O38: ='アイリス(1)'!V41 | P38: =O38=N38
B39: テストデータ予測グループ集計分布 | I39: 118 | J39: 7.7 | K39: 3.8 | L39: 6.7 | M39: 2.2 | N39: 3 | O39: ='アイリス(1)'!V42 | P39: =O39=N39
B40: predicted_label | C40: count | D40: ratio | I40: 134 | J40: 6.3 | K40: 2.8 | L40: 5.1 | M40: 1.5 | N40: 2 | O40: ='アイリス(1)'!V43 | P40: =O40=N40
B41: 1 | C41: 15 | D41: 0.33333333 | I41: 89 | J41: 5.6 | K41: 3 | L41: 4.1 | M41: 1.3 | N41: 2 | O41: ='アイリス(1)'!V44 | P41: =O41=N41
B42: 2 | C42: 15 | D42: 0.33333333 | I42: 119 | J42: 7.7 | K42: 2.6 | L42: 6.9 | M42: 2.3 | N42: 3 | O42: ='アイリス(1)'!V45 | P42: =O42=N42
B43: 3 | C43: 15 | D43: 0.33333333 | I43: 117 | J43: 6.5 | K43: 3 | L43: 5.5 | M43: 1.8 | N43: 3 | O43: ='アイリス(1)'!V46 | P43: =O43=N43
...
